<testsuite name="Mocha Tests" tests="2" failures="1" errors="1" skipped="0" timestamp="2016-05-21T10:07:02" time="0.012">
<testcase classname="test1 foo1" name="Should work properly" time="0"/>
<testcase classname="test1 foo1" name="should throw exception" time="0.004"><failure message="expected [Function] to throw Error"><![CDATA[AssertionError: expected [Function] to throw Error
    at Context.&lt;anonymous&gt; (D:\My Documents D\Stulsoft\ys-pnodejs\modules\pmocha\test\test1.js:11:58)
    at callFn (C:\Users\user\AppData\Roaming\npm\node_modules\mocha\lib\runnable.js:315:21)
    at Test.Runnable.run (C:\Users\user\AppData\Roaming\npm\node_modules\mocha\lib\runnable.js:308:7)
    at Runner.runTest (C:\Users\user\AppData\Roaming\npm\node_modules\mocha\lib\runner.js:422:10)
    at C:\Users\user\AppData\Roaming\npm\node_modules\mocha\lib\runner.js:533:12
    at next (C:\Users\user\AppData\Roaming\npm\node_modules\mocha\lib\runner.js:342:14)
    at C:\Users\user\AppData\Roaming\npm\node_modules\mocha\lib\runner.js:352:7
    at next (C:\Users\user\AppData\Roaming\npm\node_modules\mocha\lib\runner.js:284:14)
    at Immediate._onImmediate (C:\Users\user\AppData\Roaming\npm\node_modules\mocha\lib\runner.js:320:5)]]></failure></testcase>
</testsuite>
